{"name": "test_xfail_expected_failure", "status": "skipped", "statusDetails": {"message": "AssertionError: assert False", "trace": "@pytest.mark.xfail(condition=lambda: True, reason='this test is expecting failure')\n    def test_xfail_expected_failure():\n        \"\"\"this test is an xfail that will be marked as expected failure\"\"\"\n>       assert False\nE       assert False\n\ntest_failure.py:7: AssertionError"}, "description": "this test is an xfail that will be marked as expected failure", "start": 1588906491709, "stop": 1588906491709, "uuid": "c254fe53-989e-4b35-bcd5-9f01a8433611", "historyId": "4e6959817de09b843e6633ce25627cdb", "testCaseId": "561af9971b64961dde498e7d1f91d0fd", "fullName": "test_failure#test_xfail_expected_failure", "labels": [{"name": "suite", "value": "test_failure"}, {"name": "host", "value": "pinrongdeMacBook-Pro.local"}, {"name": "thread", "value": "90385-MainThread"}, {"name": "framework", "value": "pytest"}, {"name": "language", "value": "cpython3"}, {"name": "package", "value": "test_failure"}]}